
  0%|                                                                                                                                                                                                                                                                               | 0/2181 [00:00<?, ?it/s]Traceback (most recent call last):
  File "/home/xuruyi/myLLaVa/LLAVA_UHD/llava_uhd/train/llava-uhd/train_mem.py", line 14, in <module>
    train()
  File "/home/xuruyi/myLLaVa/LLAVA_UHD/llava_uhd/train/llava-uhd/train.py", line 1007, in train
    model.config.use_cache = True
  File "/home/xuruyi/miniconda3/envs/newllava/lib/python3.10/site-packages/transformers/trainer.py", line 1539, in train
    return inner_training_loop(
  File "/home/xuruyi/miniconda3/envs/newllava/lib/python3.10/site-packages/transformers/trainer.py", line 1787, in _inner_training_loop
    for step, inputs in enumerate(epoch_iterator):
  File "/home/xuruyi/miniconda3/envs/newllava/lib/python3.10/site-packages/accelerate/data_loader.py", line 384, in __iter__
    current_batch = next(dataloader_iter)
  File "/home/xuruyi/miniconda3/envs/newllava/lib/python3.10/site-packages/torch/utils/data/dataloader.py", line 633, in __next__
    data = self._next_data()
  File "/home/xuruyi/miniconda3/envs/newllava/lib/python3.10/site-packages/torch/utils/data/dataloader.py", line 1345, in _next_data
    return self._process_data(data)
  File "/home/xuruyi/miniconda3/envs/newllava/lib/python3.10/site-packages/torch/utils/data/dataloader.py", line 1371, in _process_data
    data.reraise()
  File "/home/xuruyi/miniconda3/envs/newllava/lib/python3.10/site-packages/torch/_utils.py", line 644, in reraise
    raise exception
TypeError: Caught TypeError in DataLoader worker process 0.
Original Traceback (most recent call last):
  File "/home/xuruyi/miniconda3/envs/newllava/lib/python3.10/site-packages/torch/utils/data/_utils/worker.py", line 308, in _worker_loop
    data = fetcher.fetch(index)
  File "/home/xuruyi/miniconda3/envs/newllava/lib/python3.10/site-packages/torch/utils/data/_utils/fetch.py", line 54, in fetch
    return self.collate_fn(data)
  File "/home/xuruyi/myLLaVa/LLAVA_UHD/llava_uhd/train/llava-uhd/train.py", line 773, in __call__
    batch['images'] = torch.stack(padded_x_tensor)
TypeError: stack(): argument 'tensors' (position 1) must be tuple of Tensors, not Tensor